<?xml version="1.0" encoding="utf-8"?>
<!-- This URDF was automatically created by SolidWorks to URDF Exporter! Originally created by Stephen Brawner (brawner@gmail.com) 
     Commit Version: 1.6.0-1-g15f4949  Build Version: 1.6.7594.29634
     For more information, please see http://wiki.ros.org/sw_urdf_exporter -->
<robot
  name="raibo_arm">
  <link
    name="base">
    <inertial>
      <origin
        xyz="-0.00029991 0.00016404 -0.03744115"
        rpy="0 0 0" />
      <mass
        value="12.37167760" />
      <inertia
        ixx="0.09099956"
        ixy="0.00086574"
        ixz="0.00061281"
        iyy="0.31985024"
        iyz="-0.00010439"
        izz="0.38017107" />
    </inertial>
    <visual>
      <origin
        xyz="0 0 0"
        rpy="0 0 0" />
      <geometry>
        <mesh
          filename="base.STL" />
      </geometry>
      <material
        name="">
        <color
          rgba="0.75294 0.75294 0.75294 1" />
      </material>
    </visual>
    <collision>
      <origin
        xyz="0 0 -0.03625"
        rpy="0 0 0" />
      <geometry>
        <box size="0.494 0.160 0.120"/>
      </geometry>
    </collision>
    <collision>
      <origin
        xyz="0 0 -0.03625"
        rpy="0 0 0" />
      <geometry>
        <box size="0.494 0.242 0.082"/>
      </geometry>
    </collision>
    <collision>
      <origin
        xyz="0 0 -0.03625"
        rpy="0 0 0" />
      <geometry>
        <box size="0.494 0.276 0.001"/>
      </geometry>
    </collision>
  </link>
  <link
    name="LF_HIP">
    <inertial>
      <origin
        xyz="-0.01076416 -0.02789344 0.00001059"
        rpy="0 0 0" />
      <mass
        value="1.29077719" />
      <inertia
        ixx="0.00098519"
        ixy="-0.00038663"
        ixz="0.00000019"
        iyy="0.00159759"
        iyz="-0.00000034"
        izz="0.00161789" />
    </inertial>
    <visual>
      <origin
        xyz="0 0 0"
        rpy="0 0 0" />
      <geometry>
        <mesh
          filename="LF_HIP.STL" />
      </geometry>
      <material
        name="">
        <color
          rgba="0.89804 0.91765 0.92941 1" />
      </material>
    </visual>
    <collision>
      <origin
        rpy="1.57079632679 0 0"
        xyz="0 0.036 0"/>
      <geometry>
        <cylinder length="0.1228" radius="0.048"/>
      </geometry>
    </collision>
    <collision>
      <origin
        rpy="1.57079632679 0 0"
        xyz="0 -0.0325 0"/>
      <geometry>
        <cylinder length="0.0396" radius="0.044"/>
      </geometry>
    </collision>
  </link>
  <joint
    name="LF_HAA"
    type="revolute">
    <origin
      xyz="0.3072 0.08 -0.03625"
      rpy="0 0 0" />
    <parent
      link="base" />
    <child
      link="LF_HIP" />
    <axis
      xyz="1 0 0" />
    <limit
      lower="-3.1416"
      upper="3.1416"
      effort="63.45"
      velocity="25.7" />
    <dynamics
      rotor_inertia="0.005741839" />
  </joint>
  <link
    name="LF_THIGH">
    <inertial>
      <origin
        xyz="-0.00274830 -0.03667330 -0.03252796"
        rpy="0 0 0" />
      <mass
        value="1.96391657" />
      <inertia
        ixx="0.01250320"
        ixy="-0.00019782"
        ixz="0.00056475"
        iyy="0.01152322"
        iyz="-0.00237505"
        izz="0.00260694" />
    </inertial>
    <visual>
      <origin
        xyz="0 0 0"
        rpy="0 0 0" />
      <geometry>
        <mesh
          filename="LF_THIGH.STL" />
      </geometry>
      <material
        name="">
        <color
          rgba="0.89804 0.91765 0.92941 1" />
      </material>
    </visual>
    <collision>
      <origin rpy="0 1.57079632679 0" xyz="-0.02322 0 -0.120"/>
      <geometry>
        <box size="0.220 0.040 0.044"/>
      </geometry>
    </collision>
    <collision>
      <origin rpy="1.57079632679 0 0" xyz="0 0 -0.240"/>
      <geometry>
        <cylinder length="0.053" radius="0.0265"/>
      </geometry>
    </collision>
  </link>
  <joint
    name="LF_HFE"
    type="revolute">
    <origin
      xyz="0 0.0889 0"
      rpy="0 0 0" />
    <parent
      link="LF_HIP" />
    <child
      link="LF_THIGH" />
    <axis
      xyz="0 1 0" />
    <limit
      lower="-6.2832"
      upper="6.2832"
      effort="63.45"
      velocity="25.7" />
    <dynamics
       rotor_inertia="0.005741839" />
  </joint>
  <link
    name="LF_SHANK">
    <inertial>
      <origin
        xyz="0.00130151 0.00028383 -0.07226528"
        rpy="0 0 0" />
      <mass
        value="0.29554748" />
      <inertia
        ixx="0.00272392"
        ixy="-0.00000023"
        ixz="-0.00006457"
        iyy="0.00273312"
        iyz="0.00000543"
        izz="0.00008268" />
    </inertial>
    <visual>
      <origin
        xyz="0 0 0"
        rpy="0 0 0" />
      <geometry>
        <mesh
          filename="LF_SHANK.STL" />
      </geometry>
      <material
        name="">
        <color
          rgba="0.898039215686275 0.917647058823529 0.929411764705882 1" />
      </material>
    </visual>
    <collision>
      <origin rpy="0 1.42244334 0" xyz="0.0053 0 -0.0354"/>
      <geometry>
        <box size="0.0715 0.025 0.025"/>
      </geometry>
    </collision>
    <collision>
      <origin rpy="0 1.57100577 0" xyz="0.0103 0 -0.1544"/>
      <geometry>
        <box size="0.1711 0.020 0.0253"/>
      </geometry>
    </collision>
  </link>
  <joint
    name="LF_KFE"
    type="revolute">
    <origin
      xyz="0 0 -0.24"
      rpy="0 0 0" />
    <parent
      link="LF_THIGH" />
    <child
      link="LF_SHANK" />
    <axis
      xyz="0 1 0" />
    <limit
      lower="-2.4696"
      upper="-0.0262"
      effort="63.45"
      velocity="25.7" />
    <dynamics
       rotor_inertia="0.005741839" />
  </joint>
  <link
    name="LF_FOOT">
    <inertial>
      <origin
        xyz="-0.00051991 -0.00103462 -0.00171611"
        rpy="0 0 0" />
      <mass
        value="0.06096633" />
      <inertia
        ixx="0.00001314"
        ixy="-0.00000003"
        ixz="-0.00000063"
        iyy="0.00001600"
        iyz="-0.00000011"
        izz="0.00001501" />
    </inertial>
    <visual>
      <origin
        xyz="0 0 0"
        rpy="0 0 0" />
      <geometry>
        <mesh
          filename="LF_FOOT.STL" />
      </geometry>
      <material
        name="">
        <color
          rgba="0.298039215686275 0.298039215686275 0.298039215686275 1" />
      </material>
    </visual>
    <collision>
      <origin rpy="1.57079632679 0 0" xyz="0 0 0"/>
      <geometry>
        <sphere radius="0.0295"/>
      </geometry>
    </collision>
  </link>
  <joint
    name="LF_S2F"
    type="fixed">
    <origin
      xyz="0 0 -0.24"
      rpy="0 0 0" />
    <parent
      link="LF_SHANK" />
    <child
      link="LF_FOOT" />
    <axis
      xyz="0 0 0" />
  </joint>
  <link
    name="RF_HIP">
    <inertial>
      <origin
        xyz="-0.01073828 0.02789298 0.00001059"
        rpy="0 0 0" />
      <mass
        value="1.29077719" />
      <inertia
        ixx="0.00098523"
        ixy="0.00038772"
        ixz="0.00000010"
        iyy="0.00159830"
        iyz="0.00000034"
        izz="0.00161863" />
    </inertial>
    <visual>
      <origin
        xyz="0 0 0"
        rpy="0 0 0" />
      <geometry>
        <mesh
          filename="RF_HIP.STL" />
      </geometry>
      <material
        name="">
        <color
          rgba="0.898039215686275 0.917647058823529 0.929411764705882 1" />
      </material>
    </visual>
    <collision>
      <origin
        rpy="1.57079632679 0 0"
        xyz="0 -0.036 0"/>
      <geometry>
        <cylinder length="0.1228" radius="0.048"/>
      </geometry>
    </collision>
    <collision>
      <origin
        rpy="1.57079632679 0 0"
        xyz="0 0.0325 0"/>
      <geometry>
        <cylinder length="0.0396" radius="0.044"/>
      </geometry>
    </collision>
  </link>
  <joint
    name="RF_HAA"
    type="revolute">
    <origin
      xyz="0.3072 -0.08 -0.03625"
      rpy="0 0 0" />
    <parent
      link="base" />
    <child
      link="RF_HIP" />
    <axis
      xyz="1 0 0" />
    <limit
      lower="-3.1416"
      upper="3.1416"
      effort="63.45"
      velocity="25.7" />
    <dynamics
       rotor_inertia="0.005741839" />
  </joint>
  <link
    name="RF_THIGH">
    <inertial>
      <origin
        xyz="-0.00276626 0.03667330 -0.03253545"
        rpy="0 0 0" />
      <mass
        value="1.96391676" />
      <inertia
        ixx="0.01250229"
        ixy="0.00019679"
        ixz="0.00056362"
        iyy="0.01152207"
        iyz="0.00237461"
        izz="0.00260670" />
    </inertial>
    <visual>
      <origin
        xyz="0 0 0"
        rpy="0 0 0" />
      <geometry>
        <mesh
          filename="RF_THIGH.STL" />
      </geometry>
      <material
        name="">
        <color
          rgba="0.898039215686275 0.917647058823529 0.929411764705882 1" />
      </material>
    </visual>
    <collision>
      <origin rpy="0 1.57079632679 0" xyz="-0.02322 0 -0.120"/>
      <geometry>
        <box size="0.220 0.040 0.044"/>
      </geometry>
    </collision>
    <collision>
      <origin rpy="1.57079632679 0 0" xyz="0 0 -0.240"/>
      <geometry>
        <cylinder length="0.053" radius="0.0265"/>
      </geometry>
    </collision>
  </link>
  <joint
    name="RF_HFE"
    type="revolute">
    <origin
      xyz="0 -0.0889 0"
      rpy="0 0 0" />
    <parent
      link="RF_HIP" />
    <child
      link="RF_THIGH" />
    <axis
      xyz="0 1 0" />
    <limit
      lower="-6.2832"
      upper="6.2832"
      effort="63.45"
      velocity="25.7" />
    <dynamics
       rotor_inertia="0.005741839" />
  </joint>
  <link
    name="RF_SHANK">
    <inertial>
      <origin
        xyz="0.00130082 0.00028383 -0.07226529"
        rpy="0 0 0" />
      <mass
        value="0.29554748" />
      <inertia
        ixx="0.00272392"
        ixy="-0.00000023"
        ixz="-0.00006457"
        iyy="0.00273312"
        iyz="0.00000543"
        izz="0.00008268" />
    </inertial>
    <visual>
      <origin
        xyz="0 0 0"
        rpy="0 0 0" />
      <geometry>
        <mesh
          filename="RF_SHANK.STL" />
      </geometry>
      <material
        name="">
        <color
          rgba="0.898039215686275 0.917647058823529 0.929411764705882 1" />
      </material>
    </visual>
    <collision>
      <origin rpy="0 1.42244334 0" xyz="0.0053 0 -0.0354"/>
      <geometry>
        <box size="0.0715 0.025 0.025"/>
      </geometry>
    </collision>
    <collision>
      <origin rpy="0 1.57100577 0" xyz="0.0103 0 -0.1544"/>
      <geometry>
        <box size="0.1711 0.020 0.0253"/>
      </geometry>
    </collision>
  </link>
  <joint
    name="RF_KFE"
    type="revolute">
    <origin
      xyz="0 0 -0.24"
      rpy="0 0 0" />
    <parent
      link="RF_THIGH" />
    <child
      link="RF_SHANK" />
    <axis
      xyz="0 1 0" />
    <limit
      lower="-2.4696"
      upper="-0.0262"
      effort="63.45"
      velocity="25.7" />
    <dynamics
       rotor_inertia="0.005741839" />
  </joint>
  <link
    name="RF_FOOT">
    <inertial>
      <origin
        xyz="-0.00051991 -0.00103462 -0.00171611"
        rpy="0 0 0" />
      <mass
        value="0.06096633" />
      <inertia
        ixx="0.00001314"
        ixy="-0.00000003"
        ixz="-0.00000063"
        iyy="0.00001600"
        iyz="-0.00000011"
        izz="0.00001501" />
    </inertial>
    <visual>
      <origin
        xyz="0 0 0"
        rpy="0 0 0" />
      <geometry>
        <mesh
          filename="RF_FOOT.STL" />
      </geometry>
      <material
        name="">
        <color
          rgba="0.298039215686275 0.298039215686275 0.298039215686275 1" />
      </material>
    </visual>
    <collision>
      <origin rpy="1.57079632679 0 0" xyz="0 0 0"/>
      <geometry>
        <sphere radius="0.0295"/>
      </geometry>
    </collision>
  </link>
  <joint
    name="RF_S2F"
    type="fixed">
    <origin
      xyz="0 0 -0.24"
      rpy="0 0 0" />
    <parent
      link="RF_SHANK" />
    <child
      link="RF_FOOT" />
    <axis
      xyz="0 0 0" />
  </joint>
  <link
    name="LH_HIP">
    <inertial>
      <origin
        xyz="0.01073455 -0.02789344 -0.00000109"
        rpy="0 0 0" />
      <mass
        value="1.29077719" />
      <inertia
        ixx="0.00098523"
        ixy="0.00038778"
        ixz="0.00000000"
        iyy="0.00159841"
        iyz="0.00000013"
        izz="0.00161867" />
    </inertial>
    <visual>
      <origin
        xyz="0 0 0"
        rpy="0 0 0" />
      <geometry>
        <mesh
          filename="LH_HIP.STL" />
      </geometry>
      <material
        name="">
        <color
          rgba="0.898039215686275 0.917647058823529 0.929411764705882 1" />
      </material>
    </visual>
    <collision>
      <origin
        rpy="1.57079632679 0 0"
        xyz="0 0.036 0"/>
      <geometry>
        <cylinder length="0.1228" radius="0.048"/>
      </geometry>
    </collision>
    <collision>
      <origin
        rpy="1.57079632679 0 0"
        xyz="0 -0.0325 0"/>
      <geometry>
        <cylinder length="0.0396" radius="0.044"/>
      </geometry>
    </collision>
  </link>
  <joint
    name="LH_HAA"
    type="revolute">
    <origin
      xyz="-0.3072 0.08 -0.03625"
      rpy="0 0 0" />
    <parent
      link="base" />
    <child
      link="LH_HIP" />
    <axis
      xyz="1 0 0" />
    <limit
      lower="-3.1416"
      upper="3.1416"
      effort="63.45"
      velocity="25.7" />
    <dynamics
       rotor_inertia="0.005741839" />
  </joint>
  <link
    name="LH_THIGH">
    <inertial>
      <origin
        xyz="-0.00274824 -0.03667330 -0.03252704"
        rpy="0 0 0" />
      <mass
        value="1.96391657" />
      <inertia
        ixx="0.01250319"
        ixy="-0.00019783"
        ixz="0.00056475"
        iyy="0.01152322"
        iyz="-0.00237504"
        izz="0.00260694" />
    </inertial>
    <visual>
      <origin
        xyz="0 0 0"
        rpy="0 0 0" />
      <geometry>
        <mesh
          filename="LH_THIGH.STL" />
      </geometry>
      <material
        name="">
        <color
          rgba="0.898039215686275 0.917647058823529 0.929411764705882 1" />
      </material>
    </visual>
    <collision>
      <origin rpy="0 1.57079632679 0" xyz="-0.02322 0 -0.120"/>
      <geometry>
        <box size="0.220 0.040 0.044"/>
      </geometry>
    </collision>
    <collision>
      <origin rpy="1.57079632679 0 0" xyz="0 0 -0.240"/>
      <geometry>
        <cylinder length="0.053" radius="0.0265"/>
      </geometry>
    </collision>
  </link>
  <joint
    name="LH_HFE"
    type="revolute">
    <origin
      xyz="0 0.0889 0"
      rpy="0 0 0" />
    <parent
      link="LH_HIP" />
    <child
      link="LH_THIGH" />
    <axis
      xyz="0 1 0" />
    <limit
      lower="-6.2832"
      upper="6.2832"
      effort="63.45"
      velocity="25.7" />
    <dynamics
       rotor_inertia="0.005741839" />
  </joint>
  <link
    name="LH_SHANK">
    <inertial>
      <origin
        xyz="0.00130151 0.00028383 -0.07226525"
        rpy="0 0 0" />
      <mass
        value="0.29554748" />
      <inertia
        ixx="0.00272392"
        ixy="-0.00000023"
        ixz="-0.00006457"
        iyy="0.00273312"
        iyz="0.00000543"
        izz="0.00008268" />
    </inertial>
    <visual>
      <origin
        xyz="0 0 0"
        rpy="0 0 0" />
      <geometry>
        <mesh
          filename="LH_SHANK.STL" />
      </geometry>
      <material
        name="">
        <color
          rgba="0.898039215686275 0.917647058823529 0.929411764705882 1" />
      </material>
    </visual>
    <collision>
      <origin rpy="0 1.42244334 0" xyz="0.0053 0 -0.0354"/>
      <geometry>
        <box size="0.0715 0.025 0.025"/>
      </geometry>
    </collision>
    <collision>
      <origin rpy="0 1.57100577 0" xyz="0.0103 0 -0.1544"/>
      <geometry>
        <box size="0.1711 0.020 0.0253"/>
      </geometry>
    </collision>
  </link>
  <joint
    name="LH_KFE"
    type="revolute">
    <origin
      xyz="0 0 -0.24"
      rpy="0 0 0" />
    <parent
      link="LH_THIGH" />
    <child
      link="LH_SHANK" />
    <axis
      xyz="0 1 0" />
    <limit
      lower="-2.4696"
      upper="-0.0262"
      effort="63.45"
      velocity="25.7" />
    <dynamics
       rotor_inertia="0.005741839" />
  </joint>
  <link
    name="LH_FOOT">
    <inertial>
      <origin
        xyz="-0.00051991 -0.00103462 -0.00171611"
        rpy="0 0 0" />
      <mass
        value="0.06096633" />
      <inertia
        ixx="0.00001314"
        ixy="-0.00000003"
        ixz="-0.00000063"
        iyy="0.00001600"
        iyz="-0.00000011"
        izz="0.00001501" />
    </inertial>
    <visual>
      <origin
        xyz="0 0 0"
        rpy="0 0 0" />
      <geometry>
        <mesh
          filename="LH_FOOT.STL" />
      </geometry>
      <material
        name="">
        <color
          rgba="0.298039215686275 0.298039215686275 0.298039215686275 1" />
      </material>
    </visual>
    <collision>
      <origin rpy="1.57079632679 0 0" xyz="0 0 0"/>
      <geometry>
        <sphere radius="0.0295"/>
      </geometry>
    </collision>
  </link>
  <joint
    name="LH_S2F"
    type="fixed">
    <origin
      xyz="0 0 -0.24"
      rpy="0 0 0" />
    <parent
      link="LH_SHANK" />
    <child
      link="LH_FOOT" />
    <axis
      xyz="0 0 0" />
  </joint>
  <link
    name="RH_HIP">
    <inertial>
      <origin
        xyz="0.01074969 0.02789298 -0.00001644"
        rpy="0 0 0" />
      <mass
        value="1.29077719" />
      <inertia
        ixx="0.00098517"
        ixy="-0.00038732"
        ixz="0.00000022"
        iyy="0.00159798"
        iyz="-0.00000061"
        izz="0.00161837" />
    </inertial>
    <visual>
      <origin
        xyz="0 0 0"
        rpy="0 0 0" />
      <geometry>
        <mesh
          filename="RH_HIP.STL" />
      </geometry>
      <material
        name="">
        <color
          rgba="0.898039215686275 0.917647058823529 0.929411764705882 1" />
      </material>
    </visual>
    <collision>
      <origin
        rpy="1.57079632679 0 0"
        xyz="0 -0.036 0"/>
      <geometry>
        <cylinder length="0.1228" radius="0.048"/>
      </geometry>
    </collision>
    <collision>
      <origin
        rpy="1.57079632679 0 0"
        xyz="0 0.0325 0"/>
      <geometry>
        <cylinder length="0.0396" radius="0.044"/>
      </geometry>
    </collision>
  </link>
  <joint
    name="RH_HAA"
    type="revolute">
    <origin
      xyz="-0.3072 -0.08 -0.03625"
      rpy="0 0 0" />
    <parent
      link="base" />
    <child
      link="RH_HIP" />
    <axis
      xyz="1 0 0" />
    <limit
      lower="-3.1416"
      upper="3.1416"
      effort="63.45"
      velocity="25.7" />
    <dynamics
       rotor_inertia="0.005741839" />
  </joint>
  <link
    name="RH_THIGH">
    <inertial>
      <origin
        xyz="-0.00275637 0.03667150 -0.03254657"
        rpy="0 0 0" />
      <mass
        value="1.96391676" />
      <inertia
        ixx="0.01250094"
        ixy="0.00019734"
        ixz="0.00056417"
        iyy="0.01152066"
        iyz="0.00237400"
        izz="0.00260716" />
    </inertial>
    <visual>
      <origin
        xyz="0 0 0"
        rpy="0 0 0" />
      <geometry>
        <mesh
          filename="RH_THIGH.STL" />
      </geometry>
      <material
        name="">
        <color
          rgba="0.898039215686275 0.917647058823529 0.929411764705882 1" />
      </material>
    </visual>
    <collision>
      <origin rpy="0 1.57079632679 0" xyz="-0.02322 0 -0.120"/>
      <geometry>
        <box size="0.220 0.040 0.044"/>
      </geometry>
    </collision>
    <collision>
      <origin rpy="1.57079632679 0 0" xyz="0 0 -0.240"/>
      <geometry>
        <cylinder length="0.053" radius="0.0265"/>
      </geometry>
    </collision>
  </link>
  <joint
    name="RH_HFE"
    type="revolute">
    <origin
      xyz="0 -0.0889 0"
      rpy="0 0 0" />
    <parent
      link="RH_HIP" />
    <child
      link="RH_THIGH" />
    <axis
      xyz="0 1 0" />
    <limit
      lower="-6.2832"
      upper="6.2832"
      effort="63.45"
      velocity="25.7" />
    <dynamics
       rotor_inertia="0.005741839" />
  </joint>
  <link
    name="RH_SHANK">
    <inertial>
      <origin
        xyz="0.00130151 0.00028383 -0.07226529"
        rpy="0 0 0" />
      <mass
        value="0.29554748 " />
      <inertia
        ixx="0.00272392"
        ixy="-0.00000023"
        ixz="-0.00006457"
        iyy="0.00273312"
        iyz="0.00000543"
        izz="0.00008268" />
    </inertial>
    <visual>
      <origin
        xyz="0 0 0"
        rpy="0 0 0" />
      <geometry>
        <mesh
          filename="RH_SHANK.STL" />
      </geometry>
      <material
        name="">
        <color
          rgba="0.898039215686275 0.917647058823529 0.929411764705882 1" />
      </material>
    </visual>
    <collision>
      <origin rpy="0 1.42244334 0" xyz="0.0053 0 -0.0354"/>
      <geometry>
        <box size="0.0715 0.025 0.025"/>
      </geometry>
    </collision>
    <collision>
      <origin rpy="0 1.57100577 0" xyz="0.0103 0 -0.1544"/>
      <geometry>
        <box size="0.1711 0.020 0.0253"/>
      </geometry>
    </collision>
  </link>
  <joint
    name="RH_KFE"
    type="revolute">
    <origin
      xyz="0 0 -0.24"
      rpy="0 0 0" />
    <parent
      link="RH_THIGH" />
    <child
      link="RH_SHANK" />
    <axis
      xyz="0 1 0" />
    <limit
      lower="-2.4696"
      upper="-0.0262"
      effort="63.45"
      velocity="25.7" />
    <dynamics
       rotor_inertia="0.005741839" />
  </joint>
  <link
    name="RH_FOOT">
    <inertial>
      <origin
        xyz="-0.00051991 -0.00103462 -0.00171611"
        rpy="0 0 0" />
      <mass
        value="0.06096633" />
      <inertia
        ixx="0.00001314"
        ixy="-0.00000003"
        ixz="-0.00000063"
        iyy="0.00001600"
        iyz="-0.00000011"
        izz="0.00001501" />
    </inertial>
    <visual>
      <origin
        xyz="0 0 0"
        rpy="0 0 0" />
      <geometry>
        <mesh
          filename="RH_FOOT.STL" />
      </geometry>
      <material
        name="">
        <color
          rgba="0.298039215686275 0.298039215686275 0.298039215686275 1" />
      </material>
    </visual>
    <collision>
      <origin rpy="1.57079632679 0 0" xyz="0 0 0"/>
      <geometry>
        <sphere radius="0.0295"/>
      </geometry>
    </collision>
  </link>
  <joint
    name="RH_S2F"
    type="fixed">
    <origin
      xyz="0 0 -0.24"
      rpy="0 0 0" />
    <parent
      link="RH_SHANK" />
    <child
      link="RH_FOOT" />
    <axis
      xyz="0 0 0" />
  </joint>

  <link
    name="base_link">
    <inertial>
      <origin
        xyz="-2.6676E-06 6.6431E-05 0.035814"
        rpy="0 0 0" />
      <mass
        value="0.40931" />
      <inertia
        ixx="0.00025674"
        ixy="4.2386E-06"
        ixz="-1.4089E-09"
        iyy="0.00024856"
        iyz="3.536E-09"
        izz="0.00045579" />
    </inertial>
    <visual>
      <origin
        xyz="0 0 0"
        rpy="0 0 0" />
      <geometry>
        <mesh
          filename="../meshes/base_link.STL" />
      </geometry>
      <material
        name="">
        <color
          rgba="0.75294 0.75294 0.75294 1" />
      </material>
    </visual>
  </link>

  <joint name="kinova_joint_base" type="fixed">
    <parent link="base"/>
    <child link="base_link"/>
    <origin rpy="0 0 0" xyz="0.15 0 0"/>
  </joint>

  <link
    name="link1">
    <inertial>
      <origin
        xyz="2.0778E-07 0.025925 0.051746"
        rpy="0 0 0" />
      <mass
        value="0.42204" />
      <inertia
        ixx="0.00026117"
        ixy="8.9791E-11"
        ixz="1.0579E-07"
        iyy="0.00046901"
        iyz="4.9903E-09"
        izz="0.00025926" />
    </inertial>
    <visual>
      <origin
        xyz="0 0 0"
        rpy="0 0 0" />
      <geometry>
        <mesh
          filename="../meshes/link1.STL" />
      </geometry>
      <material
        name="">
        <color
          rgba="0.75294 0.75294 0.75294 1" />
      </material>
    </visual>
    <collision>
      <origin
        xyz="0 0 0"
        rpy="0 0 0" />
      <geometry>
        <mesh
          filename="../meshes/link1.obj" />
      </geometry>
    </collision>
  </link>
  <joint
    name="joint1"
    type="revolute">
    <origin
      xyz="0 6.0353E-05 0.066545"
      rpy="0 0 -0.45605" />
    <parent
      link="base_link" />
    <child
      link="link1" />
    <axis
      xyz="0 0 -1" />
    <limit
      lower="-6.28"
      upper="6.28"
      effort="80"
      velocity="20" />
  </joint>
  <link
    name="link2">
    <inertial>
      <origin
        xyz="-0.056805 0.037306 0.05852"
        rpy="0 0 0" />
      <mass
        value="0.84768" />
      <inertia
        ixx="0.0030313"
        ixy="0.0027774"
        ixz="2.9197E-05"
        iyy="0.003718"
        iyz="6.2474E-06"
        izz="0.0065672" />
    </inertial>
    <visual>
      <origin
        xyz="0 0 0"
        rpy="0 0 0" />
      <geometry>
        <mesh
          filename="../meshes/link2.STL" />
      </geometry>
      <material
        name="">
        <color
          rgba="0.75294 0.75294 0.75294 1" />
      </material>
    </visual>
    <collision>
      <origin
        xyz="0 0 0"
        rpy="0 0 0" />
      <geometry>
        <mesh
          filename="../meshes/link2.obj" />
      </geometry>
    </collision>
  </link>
  <joint
    name="joint2"
    type="revolute">
    <origin
      xyz="0 -0.007 0.053"
      rpy="1.5708 -0.19845 0" />
    <parent
      link="link1" />
    <child
      link="link2" />
    <axis
      xyz="0 0 -1" />
    <limit
      lower="-6.28"
      upper="6.28"
      effort="80"
      velocity="20" />
  </joint>
  <link
    name="link3">
    <inertial>
      <origin
        xyz="-0.0444249520614745 -1.55924068481195E-05 -1.05634184573156E-06"
        rpy="0 0 0" />
      <mass
        value="0.300280421855983" />
      <inertia
        ixx="0.00017841651959097"
        ixy="-1.62939417234611E-08"
        ixz="7.85077719638834E-11"
        iyy="0.000136798761787988"
        iyz="-1.46174432775188E-06"
        izz="0.000136947477002973" />
    </inertial>
    <visual>
      <origin
        xyz="0 0 0"
        rpy="0 0 0" />
      <geometry>
        <mesh
          filename="../meshes/link3.STL" />
      </geometry>
      <material
        name="">
        <color
          rgba="0.752941176470588 0.752941176470588 0.752941176470588 1" />
      </material>
    </visual>
    <collision>
      <origin
        xyz="0 0 0"
        rpy="0 0 0" />
      <geometry>
        <mesh
          filename="../meshes/link3.obj" />
      </geometry>
    </collision>
  </link>
  <joint
    name="joint3"
    type="revolute">
    <origin
      xyz="-0.22627 0.22627 0.08265"
      rpy="3.1416 0 -2.1523" />
    <parent
      link="link2" />
    <child
      link="link3" />
    <axis
      xyz="0 0 1" />
    <limit
      lower="-3.14"
      upper="0.4"
      effort="80"
      velocity="20" />
  </joint>
  <link
    name="link4">
    <inertial>
      <origin
        xyz="0.0020612307142269 -0.00735031307224393 0.319122580707953"
        rpy="0 0 0" />
      <mass
        value="0.322493892765723" />
      <inertia
        ixx="0.000494785654256079"
        ixy="-1.98265054493801E-05"
        ixz="1.01227889981719E-06"
        iyy="0.000559205616698159"
        iyz="2.86530389277511E-07"
        izz="0.00010097509421591" />
    </inertial>
    <visual>
      <origin
        xyz="0 0 0"
        rpy="0 0 0" />
      <geometry>
        <mesh
          filename="../meshes/link4.STL" />
      </geometry>
      <material
        name="">
        <color
          rgba="0.752941176470588 0.752941176470588 0.752941176470588 1" />
      </material>
    </visual>
    <collision>
      <origin
        xyz="0 0 0"
        rpy="0 0 0" />
      <geometry>
        <mesh
          filename="../meshes/link4.obj" />
      </geometry>
    </collision>
  </link>
  <joint
    name="joint4"
    type="revolute">
    <origin
      xyz="-0.070002 0 0"
      rpy="1.5708 1.063 -1.5708" />
    <parent
      link="link3" />
    <child
      link="link4" />
    <axis
      xyz="0 0 -1" />
    <limit
      lower="-6.28"
      upper="6.28"
      effort="40"
      velocity="20" />
  </joint>
  <link
    name="link5">
    <inertial>
      <origin
        xyz="-0.0670412479622793 -1.4068689488389E-06 -0.0255194202186986"
        rpy="0 0 0" />
      <mass
        value="0.270793262476203" />
      <inertia
        ixx="0.000177289557334705"
        ixy="-8.32059212755611E-11"
        ixz="-1.16011852007938E-05"
        iyy="0.000122719341998521"
        iyz="1.03469981956808E-06"
        izz="0.000107111604438449" />
    </inertial>
    <visual>
      <origin
        xyz="0 0 0"
        rpy="0 0 0" />
      <geometry>
        <mesh
          filename="../meshes/link5.STL" />
      </geometry>
      <material
        name="">
        <color
          rgba="0.752941176470588 0.752941176470588 0.752941176470588 1" />
      </material>
    </visual>
    <collision>
      <origin
        xyz="0 0 0"
        rpy="0 0 0" />
      <geometry>
        <mesh
          filename="../meshes/link5.obj" />
      </geometry>
    </collision>
  </link>
  <joint
    name="joint5"
    type="revolute">
    <origin
      xyz="0.0076283 -0.026945 0.359"
      rpy="-1.5708 1.3723 -2.8657" />
    <parent
      link="link4" />
    <child
      link="link5" />
    <axis
      xyz="0 0 1" />
    <limit
      lower="-1.8"
      upper="1.8"
      effort="40"
      velocity="20" />
  </joint>
  <link
    name="link6">
    <inertial>
      <origin
        xyz="-1.45587353284071E-09 -3.37469850675287E-09 0.00896679159595459"
        rpy="0 0 0" />
      <mass
        value="0.00616895938082152" />
      <inertia
        ixx="1.48677013808814E-06"
        ixy="1.62190401411481E-14"
        ixz="3.45683498077009E-14"
        iyy="1.48676995228825E-06"
        iyz="6.29319939715178E-14"
        izz="2.38457325299129E-06" />
    </inertial>
    <visual>
      <origin
        xyz="0 0 0"
        rpy="0 0 0" />
      <geometry>
        <mesh
          filename="../meshes/link6.STL" />
      </geometry>
      <material
        name="">
        <color
          rgba="0.752941176470588 0.752941176470588 0.752941176470588 1" />
      </material>
    </visual>
    <collision>
      <origin
        xyz="0 0 0"
        rpy="0 0 0" />
      <geometry>
        <mesh
          filename="../meshes/link6.obj" />
      </geometry>
    </collision>
  </link>
  <joint
    name="joint6"
    type="revolute">
    <origin
      xyz="-0.088002 0 -0.028004"
      rpy="-1.5708 0.63873 1.5708" />
    <parent
      link="link5" />
    <child
      link="link6" />
    <axis
      xyz="0 0 -1" />
    <limit
      lower="-6.28"
      upper="6.28"
      effort="40"
      velocity="20" />
  </joint>

</robot>