<?xml version="1.0" encoding="utf-8"?>
<!-- This URDF was automatically created by SolidWorks to URDF Exporter! Originally created by Stephen Brawner (brawner@gmail.com) 
     Commit Version: 1.6.0-1-g15f4949  Build Version: 1.6.7594.29634
     For more information, please see http://wiki.ros.org/sw_urdf_exporter -->
<robot
  name="raibo_arm">

  <link name="world"/>

  <link
    name="base_link">
    <inertial>
      <origin
        xyz="-2.6676E-06 6.6431E-05 0.035814"
        rpy="0 0 0" />
      <mass
        value="0.40931" />
      <inertia
        ixx="0.00025674"
        ixy="4.2386E-06"
        ixz="-1.4089E-09"
        iyy="0.00024856"
        iyz="3.536E-09"
        izz="0.00045579" />
    </inertial>
    <visual>
      <origin
        xyz="0 0 0"
        rpy="0 0 0" />
      <geometry>
        <mesh
          filename="../meshes/base_link.STL" />
      </geometry>
      <material
        name="">
        <color
          rgba="0.75294 0.75294 0.75294 1" />
      </material>
    </visual>
  </link>

  <joint name="kinova_joint_base" type="fixed">
    <parent link="world"/>
    <child link="base_link"/>
    <origin rpy="0 0 0" xyz="0.15 0 0"/>
  </joint>

  <link
    name="link1">
    <inertial>
      <origin
        xyz="2.0778E-07 0.025925 0.051746"
        rpy="0 0 0" />
      <mass
        value="0.42204" />
      <inertia
        ixx="0.00026117"
        ixy="8.9791E-11"
        ixz="1.0579E-07"
        iyy="0.00046901"
        iyz="4.9903E-09"
        izz="0.00025926" />
    </inertial>
    <visual>
      <origin
        xyz="0 0 0"
        rpy="0 0 0" />
      <geometry>
        <mesh
          filename="../meshes/link1.STL" />
      </geometry>
      <material
        name="">
        <color
          rgba="0.75294 0.75294 0.75294 1" />
      </material>
    </visual>
    <collision>
      <origin
        xyz="0 0 0"
        rpy="0 0 0" />
      <geometry>
        <mesh
          filename="../meshes/link1.obj" />
      </geometry>
    </collision>
  </link>
  <joint
    name="joint1"
    type="revolute">
    <origin
      xyz="0 6.0353E-05 0.066545"
      rpy="0 0 -0.45605" />
    <parent
      link="base_link" />
    <child
      link="link1" />
    <axis
      xyz="0 0 -1" />
    <limit
      lower="-6.28"
      upper="6.28"
      effort="80"
      velocity="20" />
  </joint>
  <link
    name="link2">
    <inertial>
      <origin
        xyz="-0.056805 0.037306 0.05852"
        rpy="0 0 0" />
      <mass
        value="0.84768" />
      <inertia
        ixx="0.0030313"
        ixy="0.0027774"
        ixz="2.9197E-05"
        iyy="0.003718"
        iyz="6.2474E-06"
        izz="0.0065672" />
    </inertial>
    <visual>
      <origin
        xyz="0 0 0"
        rpy="0 0 0" />
      <geometry>
        <mesh
          filename="../meshes/link2.STL" />
      </geometry>
      <material
        name="">
        <color
          rgba="0.75294 0.75294 0.75294 1" />
      </material>
    </visual>
    <collision>
      <origin
        xyz="0 0 0"
        rpy="0 0 0" />
      <geometry>
        <mesh
          filename="../meshes/link2.obj" />
      </geometry>
    </collision>
  </link>
  <joint
    name="joint2"
    type="revolute">
    <origin
      xyz="0 -0.007 0.053"
      rpy="1.5708 -0.19845 0" />
    <parent
      link="link1" />
    <child
      link="link2" />
    <axis
      xyz="0 0 -1" />
    <limit
      lower="-6.28"
      upper="6.28"
      effort="80"
      velocity="20" />
  </joint>
  <link
    name="link3">
    <inertial>
      <origin
        xyz="-0.0444249520614745 -1.55924068481195E-05 -1.05634184573156E-06"
        rpy="0 0 0" />
      <mass
        value="0.300280421855983" />
      <inertia
        ixx="0.00017841651959097"
        ixy="-1.62939417234611E-08"
        ixz="7.85077719638834E-11"
        iyy="0.000136798761787988"
        iyz="-1.46174432775188E-06"
        izz="0.000136947477002973" />
    </inertial>
    <visual>
      <origin
        xyz="0 0 0"
        rpy="0 0 0" />
      <geometry>
        <mesh
          filename="../meshes/link3.STL" />
      </geometry>
      <material
        name="">
        <color
          rgba="0.752941176470588 0.752941176470588 0.752941176470588 1" />
      </material>
    </visual>
    <collision>
      <origin
        xyz="0 0 0"
        rpy="0 0 0" />
      <geometry>
        <mesh
          filename="../meshes/link3.obj" />
      </geometry>
    </collision>
  </link>
  <joint
    name="joint3"
    type="revolute">
    <origin
      xyz="-0.22627 0.22627 0.08265"
      rpy="3.1416 0 -2.1523" />
    <parent
      link="link2" />
    <child
      link="link3" />
    <axis
      xyz="0 0 1" />
    <limit
      lower="-3.14"
      upper="0.4"
      effort="80"
      velocity="20" />
  </joint>
  <link
    name="link4">
    <inertial>
      <origin
        xyz="0.0020612307142269 -0.00735031307224393 0.319122580707953"
        rpy="0 0 0" />
      <mass
        value="0.322493892765723" />
      <inertia
        ixx="0.000494785654256079"
        ixy="-1.98265054493801E-05"
        ixz="1.01227889981719E-06"
        iyy="0.000559205616698159"
        iyz="2.86530389277511E-07"
        izz="0.00010097509421591" />
    </inertial>
    <visual>
      <origin
        xyz="0 0 0"
        rpy="0 0 0" />
      <geometry>
        <mesh
          filename="../meshes/link4.STL" />
      </geometry>
      <material
        name="">
        <color
          rgba="0.752941176470588 0.752941176470588 0.752941176470588 1" />
      </material>
    </visual>
    <collision>
      <origin
        xyz="0 0 0"
        rpy="0 0 0" />
      <geometry>
        <mesh
          filename="../meshes/link4.obj" />
      </geometry>
    </collision>
  </link>
  <joint
    name="joint4"
    type="revolute">
    <origin
      xyz="-0.070002 0 0"
      rpy="1.5708 1.063 -1.5708" />
    <parent
      link="link3" />
    <child
      link="link4" />
    <axis
      xyz="0 0 -1" />
    <limit
      lower="-6.28"
      upper="6.28"
      effort="40"
      velocity="20" />
  </joint>
  <link
    name="link5">
    <inertial>
      <origin
        xyz="-0.0670412479622793 -1.4068689488389E-06 -0.0255194202186986"
        rpy="0 0 0" />
      <mass
        value="0.270793262476203" />
      <inertia
        ixx="0.000177289557334705"
        ixy="-8.32059212755611E-11"
        ixz="-1.16011852007938E-05"
        iyy="0.000122719341998521"
        iyz="1.03469981956808E-06"
        izz="0.000107111604438449" />
    </inertial>
    <visual>
      <origin
        xyz="0 0 0"
        rpy="0 0 0" />
      <geometry>
        <mesh
          filename="../meshes/link5.STL" />
      </geometry>
      <material
        name="">
        <color
          rgba="0.752941176470588 0.752941176470588 0.752941176470588 1" />
      </material>
    </visual>
    <collision>
      <origin
        xyz="0 0 0"
        rpy="0 0 0" />
      <geometry>
        <mesh
          filename="../meshes/link5.obj" />
      </geometry>
    </collision>
  </link>
  <joint
    name="joint5"
    type="revolute">
    <origin
      xyz="0.0076283 -0.026945 0.359"
      rpy="-1.5708 1.3723 -2.8657" />
    <parent
      link="link4" />
    <child
      link="link5" />
    <axis
      xyz="0 0 1" />
    <limit
      lower="-1.8"
      upper="1.8"
      effort="40"
      velocity="20" />
  </joint>
  <link
    name="link6">
    <inertial>
      <origin
        xyz="-1.45587353284071E-09 -3.37469850675287E-09 0.00896679159595459"
        rpy="0 0 0" />
      <mass
        value="0.00616895938082152" />
      <inertia
        ixx="1.48677013808814E-06"
        ixy="1.62190401411481E-14"
        ixz="3.45683498077009E-14"
        iyy="1.48676995228825E-06"
        iyz="6.29319939715178E-14"
        izz="2.38457325299129E-06" />
    </inertial>
    <visual>
      <origin
        xyz="0 0 0"
        rpy="0 0 0" />
      <geometry>
        <mesh
          filename="../meshes/link6.STL" />
      </geometry>
      <material
        name="">
        <color
          rgba="0.752941176470588 0.752941176470588 0.752941176470588 1" />
      </material>
    </visual>
    <collision>
      <origin
        xyz="0 0 0"
        rpy="0 0 0" />
      <geometry>
        <mesh
          filename="../meshes/link6.obj" />
      </geometry>
    </collision>
  </link>
  <joint
    name="joint6"
    type="revolute">
    <origin
      xyz="-0.088002 0 -0.028004"
      rpy="-1.5708 0.63873 1.5708" />
    <parent
      link="link5" />
    <child
      link="link6" />
    <axis
      xyz="0 0 -1" />
    <limit
      lower="-6.28"
      upper="6.28"
      effort="40"
      velocity="20" />
  </joint>

</robot>